Traceback (most recent call last):
  File "/home/mfvargas/miniconda3/envs/pf3311-2025-ii/lib/python3.13/site-packages/jupyter_core/utils/__init__.py", line 154, in wrapped
    asyncio.get_running_loop()
    ~~~~~~~~~~~~~~~~~~~~~~~~^^
RuntimeError: no running event loop

During handling of the above exception, another exception occurred:

Traceback (most recent call last):
  File "/home/mfvargas/miniconda3/envs/pf3311-2025-ii/lib/python3.13/site-packages/jupyter_cache/executors/utils.py", line 58, in single_nb_execution
    executenb(
    ~~~~~~~~~^
        nb,
        ^^^
    ...<4 lines>...
        **kwargs,
        ^^^^^^^^^
    )
    ^
  File "/home/mfvargas/miniconda3/envs/pf3311-2025-ii/lib/python3.13/site-packages/nbclient/client.py", line 1319, in execute
    return NotebookClient(nb=nb, resources=resources, km=km, **kwargs).execute()
           ~~~~~~~~~~~~~~~~~~~~~~~~~~~~~~~~~~~~~~~~~~~~~~~~~~~~~~~~~~~~~~~~~~~^^
  File "/home/mfvargas/miniconda3/envs/pf3311-2025-ii/lib/python3.13/site-packages/jupyter_core/utils/__init__.py", line 158, in wrapped
    return loop.run_until_complete(inner)
           ~~~~~~~~~~~~~~~~~~~~~~~^^^^^^^
  File "/home/mfvargas/miniconda3/envs/pf3311-2025-ii/lib/python3.13/asyncio/base_events.py", line 725, in run_until_complete
    return future.result()
           ~~~~~~~~~~~~~^^
  File "/home/mfvargas/miniconda3/envs/pf3311-2025-ii/lib/python3.13/site-packages/nbclient/client.py", line 709, in async_execute
    await self.async_execute_cell(
        cell, index, execution_count=self.code_cells_executed + 1
    )
  File "/home/mfvargas/miniconda3/envs/pf3311-2025-ii/lib/python3.13/site-packages/nbclient/client.py", line 1062, in async_execute_cell
    await self._check_raise_for_error(cell, cell_index, exec_reply)
  File "/home/mfvargas/miniconda3/envs/pf3311-2025-ii/lib/python3.13/site-packages/nbclient/client.py", line 918, in _check_raise_for_error
    raise CellExecutionError.from_cell_and_msg(cell, exec_reply_content)
nbclient.exceptions.CellExecutionError: An error occurred while executing the following cell:
------------------
# Join espacial de las capas de ASP y registros de presencia de murciÃ©lagos

asp_contienen_murcielagos = asp.sjoin(murcielagos, how="left", op="contains")

# Conteo de especies en cada ASP
asp_especies = asp_contienen_murcielagos.groupby("id").species.nunique()
asp_especies = asp_especies.reset_index() # para convertir la serie a dataframe

asp_especies.rename(columns = {'species': 'cantidad_especies_murcielagos'}, inplace = True)

asp_especies
------------------


[31m---------------------------------------------------------------------------[39m
[31mTypeError[39m                                 Traceback (most recent call last)
[36mCell[39m[36m [39m[32mIn[7][39m[32m, line 3[39m
[32m      1[39m [38;5;66;03m# Join espacial de las capas de ASP y registros de presencia de murciÃ©lagos[39;00m
[32m----> [39m[32m3[39m asp_contienen_murcielagos = [43masp[49m[43m.[49m[43msjoin[49m[43m([49m[43mmurcielagos[49m[43m,[49m[43m [49m[43mhow[49m[43m=[49m[33;43m"[39;49m[33;43mleft[39;49m[33;43m"[39;49m[43m,[49m[43m [49m[43mop[49m[43m=[49m[33;43m"[39;49m[33;43mcontains[39;49m[33;43m"[39;49m[43m)[49m
[32m      5[39m [38;5;66;03m# Conteo de especies en cada ASP[39;00m
[32m      6[39m asp_especies = asp_contienen_murcielagos.groupby([33m"[39m[33mid[39m[33m"[39m).species.nunique()

[36mFile [39m[32m~/miniconda3/envs/pf3311-2025-ii/lib/python3.13/site-packages/geopandas/geodataframe.py:2560[39m, in [36mGeoDataFrame.sjoin[39m[34m(self, df, how, predicate, lsuffix, rsuffix, **kwargs)[39m
[32m   2468[39m [38;5;28;01mdef[39;00m[38;5;250m [39m[34msjoin[39m(
[32m   2469[39m     [38;5;28mself[39m,
[32m   2470[39m     df: GeoDataFrame,
[32m   (...)[39m[32m   2475[39m     **kwargs,
[32m   2476[39m ) -> GeoDataFrame:
[32m   2477[39m [38;5;250m    [39m[33;03m"""Spatial join of two GeoDataFrames.[39;00m
[32m   2478[39m 
[32m   2479[39m [33;03m    See the User Guide page :doc:`../../user_guide/mergingdata` for details.[39;00m
[32m   (...)[39m[32m   2558[39m [33;03m    sjoin : equivalent top-level function[39;00m
[32m   2559[39m [33;03m    """[39;00m
[32m-> [39m[32m2560[39m     [38;5;28;01mreturn[39;00m [43mgeopandas[49m[43m.[49m[43msjoin[49m[43m([49m
[32m   2561[39m [43m        [49m[43mleft_df[49m[43m=[49m[38;5;28;43mself[39;49m[43m,[49m
[32m   2562[39m [43m        [49m[43mright_df[49m[43m=[49m[43mdf[49m[43m,[49m
[32m   2563[39m [43m        [49m[43mhow[49m[43m=[49m[43mhow[49m[43m,[49m
[32m   2564[39m [43m        [49m[43mpredicate[49m[43m=[49m[43mpredicate[49m[43m,[49m
[32m   2565[39m [43m        [49m[43mlsuffix[49m[43m=[49m[43mlsuffix[49m[43m,[49m
[32m   2566[39m [43m        [49m[43mrsuffix[49m[43m=[49m[43mrsuffix[49m[43m,[49m
[32m   2567[39m [43m        [49m[43m*[49m[43m*[49m[43mkwargs[49m[43m,[49m
[32m   2568[39m [43m    [49m[43m)[49m

[36mFile [39m[32m~/miniconda3/envs/pf3311-2025-ii/lib/python3.13/site-packages/geopandas/tools/sjoin.py:109[39m, in [36msjoin[39m[34m(left_df, right_df, how, predicate, lsuffix, rsuffix, distance, on_attribute, **kwargs)[39m
[32m    107[39m [38;5;28;01mif[39;00m kwargs:
[32m    108[39m     first = [38;5;28mnext[39m([38;5;28miter[39m(kwargs.keys()))
[32m--> [39m[32m109[39m     [38;5;28;01mraise[39;00m [38;5;167;01mTypeError[39;00m([33mf[39m[33m"[39m[33msjoin() got an unexpected keyword argument [39m[33m'[39m[38;5;132;01m{[39;00mfirst[38;5;132;01m}[39;00m[33m'[39m[33m"[39m)
[32m    111[39m on_attribute = _maybe_make_list(on_attribute)
[32m    113[39m _basic_checks(left_df, right_df, how, lsuffix, rsuffix, on_attribute=on_attribute)

[31mTypeError[39m: sjoin() got an unexpected keyword argument 'op'

