Traceback (most recent call last):
  File "/home/mfvargas/miniconda3/envs/pf3311-2025-ii/lib/python3.13/site-packages/jupyter_core/utils/__init__.py", line 154, in wrapped
    asyncio.get_running_loop()
    ~~~~~~~~~~~~~~~~~~~~~~~~^^
RuntimeError: no running event loop

During handling of the above exception, another exception occurred:

Traceback (most recent call last):
  File "/home/mfvargas/miniconda3/envs/pf3311-2025-ii/lib/python3.13/site-packages/jupyter_cache/executors/utils.py", line 58, in single_nb_execution
    executenb(
    ~~~~~~~~~^
        nb,
        ^^^
    ...<4 lines>...
        **kwargs,
        ^^^^^^^^^
    )
    ^
  File "/home/mfvargas/miniconda3/envs/pf3311-2025-ii/lib/python3.13/site-packages/nbclient/client.py", line 1319, in execute
    return NotebookClient(nb=nb, resources=resources, km=km, **kwargs).execute()
           ~~~~~~~~~~~~~~~~~~~~~~~~~~~~~~~~~~~~~~~~~~~~~~~~~~~~~~~~~~~~~~~~~~~^^
  File "/home/mfvargas/miniconda3/envs/pf3311-2025-ii/lib/python3.13/site-packages/jupyter_core/utils/__init__.py", line 158, in wrapped
    return loop.run_until_complete(inner)
           ~~~~~~~~~~~~~~~~~~~~~~~^^^^^^^
  File "/home/mfvargas/miniconda3/envs/pf3311-2025-ii/lib/python3.13/asyncio/base_events.py", line 725, in run_until_complete
    return future.result()
           ~~~~~~~~~~~~~^^
  File "/home/mfvargas/miniconda3/envs/pf3311-2025-ii/lib/python3.13/site-packages/nbclient/client.py", line 709, in async_execute
    await self.async_execute_cell(
        cell, index, execution_count=self.code_cells_executed + 1
    )
  File "/home/mfvargas/miniconda3/envs/pf3311-2025-ii/lib/python3.13/site-packages/nbclient/client.py", line 1062, in async_execute_cell
    await self._check_raise_for_error(cell, cell_index, exec_reply)
  File "/home/mfvargas/miniconda3/envs/pf3311-2025-ii/lib/python3.13/site-packages/nbclient/client.py", line 918, in _check_raise_for_error
    raise CellExecutionError.from_cell_and_msg(cell, exec_reply_content)
nbclient.exceptions.CellExecutionError: An error occurred while executing the following cell:
------------------
import os
import requests
import zipfile

import csv

import fiona
import fiona.crs
from shapely.geometry import Point, mapping, shape

from owslib.wfs import WebFeatureService
from geojson import dump
------------------


[31m---------------------------------------------------------------------------[39m
[31mModuleNotFoundError[39m                       Traceback (most recent call last)
[36mCell[39m[36m [39m[32mIn[1][39m[32m, line 11[39m
[32m      8[39m [38;5;28;01mimport[39;00m[38;5;250m [39m[34;01mfiona[39;00m[34;01m.[39;00m[34;01mcrs[39;00m
[32m      9[39m [38;5;28;01mfrom[39;00m[38;5;250m [39m[34;01mshapely[39;00m[34;01m.[39;00m[34;01mgeometry[39;00m[38;5;250m [39m[38;5;28;01mimport[39;00m Point, mapping, shape
[32m---> [39m[32m11[39m [38;5;28;01mfrom[39;00m[38;5;250m [39m[34;01mowslib[39;00m[34;01m.[39;00m[34;01mwfs[39;00m[38;5;250m [39m[38;5;28;01mimport[39;00m WebFeatureService
[32m     12[39m [38;5;28;01mfrom[39;00m[38;5;250m [39m[34;01mgeojson[39;00m[38;5;250m [39m[38;5;28;01mimport[39;00m dump

[31mModuleNotFoundError[39m: No module named 'owslib'

