Traceback (most recent call last):
  File "/home/mfvargas/miniconda3/envs/pf3311-2025-ii/lib/python3.13/site-packages/jupyter_core/utils/__init__.py", line 154, in wrapped
    asyncio.get_running_loop()
    ~~~~~~~~~~~~~~~~~~~~~~~~^^
RuntimeError: no running event loop

During handling of the above exception, another exception occurred:

Traceback (most recent call last):
  File "/home/mfvargas/miniconda3/envs/pf3311-2025-ii/lib/python3.13/site-packages/jupyter_cache/executors/utils.py", line 58, in single_nb_execution
    executenb(
    ~~~~~~~~~^
        nb,
        ^^^
    ...<4 lines>...
        **kwargs,
        ^^^^^^^^^
    )
    ^
  File "/home/mfvargas/miniconda3/envs/pf3311-2025-ii/lib/python3.13/site-packages/nbclient/client.py", line 1319, in execute
    return NotebookClient(nb=nb, resources=resources, km=km, **kwargs).execute()
           ~~~~~~~~~~~~~~~~~~~~~~~~~~~~~~~~~~~~~~~~~~~~~~~~~~~~~~~~~~~~~~~~~~~^^
  File "/home/mfvargas/miniconda3/envs/pf3311-2025-ii/lib/python3.13/site-packages/jupyter_core/utils/__init__.py", line 158, in wrapped
    return loop.run_until_complete(inner)
           ~~~~~~~~~~~~~~~~~~~~~~~^^^^^^^
  File "/home/mfvargas/miniconda3/envs/pf3311-2025-ii/lib/python3.13/asyncio/base_events.py", line 725, in run_until_complete
    return future.result()
           ~~~~~~~~~~~~~^^
  File "/home/mfvargas/miniconda3/envs/pf3311-2025-ii/lib/python3.13/site-packages/nbclient/client.py", line 709, in async_execute
    await self.async_execute_cell(
        cell, index, execution_count=self.code_cells_executed + 1
    )
  File "/home/mfvargas/miniconda3/envs/pf3311-2025-ii/lib/python3.13/site-packages/nbclient/client.py", line 1062, in async_execute_cell
    await self._check_raise_for_error(cell, cell_index, exec_reply)
  File "/home/mfvargas/miniconda3/envs/pf3311-2025-ii/lib/python3.13/site-packages/nbclient/client.py", line 918, in _check_raise_for_error
    raise CellExecutionError.from_cell_and_msg(cell, exec_reply_content)
nbclient.exceptions.CellExecutionError: An error occurred while executing the following cell:
------------------
# ConversiÃ³n de series a dataframe
felinos_registros_x_anio_df = pd.DataFrame({'anio':felinos_registros_x_anio.index, 'registros':felinos_registros_x_anio.values}) 

# ConversiÃ³n del tipo de la columna de aÃ±o
felinos_registros_x_anio_df["anio"] = pd.to_numeric(felinos_registros_x_anio_df["anio"], downcast='integer')
felinos_registros_x_anio_df.style.set_precision(2)

felinos_registros_x_anio_df
------------------


[31m---------------------------------------------------------------------------[39m
[31mAttributeError[39m                            Traceback (most recent call last)
[36mCell[39m[36m [39m[32mIn[24][39m[32m, line 6[39m
[32m      4[39m [38;5;66;03m# ConversiÃ³n del tipo de la columna de aÃ±o[39;00m
[32m      5[39m felinos_registros_x_anio_df[[33m"[39m[33manio[39m[33m"[39m] = pd.to_numeric(felinos_registros_x_anio_df[[33m"[39m[33manio[39m[33m"[39m], downcast=[33m'[39m[33minteger[39m[33m'[39m)
[32m----> [39m[32m6[39m [43mfelinos_registros_x_anio_df[49m[43m.[49m[43mstyle[49m[43m.[49m[43mset_precision[49m([32m2[39m)
[32m      8[39m felinos_registros_x_anio_df

[31mAttributeError[39m: 'Styler' object has no attribute 'set_precision'

